<?xml version="1.0" encoding="utf-8"?>

<robot xmlns:xacro="http://wiki.ros.org/xacro" name="forklift_simulation">


              <!-- _____________________LINKS___________________-->


<!-- Base Footprint Link -->
  <link name="base_footprint"/>

<!-- Chassis Link -->
  <link name="chassis">
    <inertial>
      <origin xyz="0.041308 0.00011665 0.21099" rpy="0 0 0"/>
      <mass value="79.173"/>
      <inertia ixx="1.7717" ixy="0.0070117" ixz="-0.21444" iyy="2.3738" iyz="0.11565" izz="1.7629"/>
    </inertial>
    <visual>
      <origin xyz="0 0 0" rpy="0 0 0"/>
      <geometry>
        <mesh filename="package://forklift_simulation/description/meshes/chassis.STL"/>
      </geometry>
      <material name="">
        <color rgba="0.65098 0.61961 0.58824 1"/>
      </material>
    </visual>
    <collision>
      <origin xyz="0 0 0" rpy="0 0 0"/>
      <geometry>
        <mesh filename="package://forklift_simulation/description/meshes/chassis_collision.STL"/>
      </geometry>
    </collision>
  </link>

<!-- Right Wheel Link -->
  <link name="right_wheel">
    <inertial>
      <origin xyz="-4.4082E-16 -4.7184E-15 0.0055" rpy="0 0 0"/>
      <mass value="1.8562"/>
      <inertia ixx="0.0085255" ixy="-1.3145E-18" ixz="-2.1561E-19" iyy="0.0085255" iyz="-2.4865E-18" izz="0.016487"/>
    </inertial>
    <visual>
      <origin xyz="0 0 0" rpy="0 0 0"/>
      <geometry>
        <mesh filename="package://forklift_simulation/description/meshes/right_wheel.STL"/>
      </geometry>
      <material name="">
        <color rgba="0.29804 0.29804 0.29804 1"/>
      </material>
    </visual>
    <collision>
      <origin xyz="0 0 0" rpy="0 0 0"/>
      <geometry>
        <mesh filename="package://forklift_simulation/description/meshes/right_wheel.STL"/>
      </geometry>
    </collision>
  </link>

<!-- Left Wheel Link -->
  <link name="left_wheel">
    <inertial>
      <origin xyz="-1.3079E-16 -6.4393E-15 -0.0055" rpy="0 0 0"/>
      <mass value="1.8562"/>
      <inertia ixx="0.0085255" ixy="3.3171E-19" ixz="-2.9592E-19" iyy="0.0085255" iyz="-8.0528E-19" izz="0.016487"/>
    </inertial>
    <visual>
      <origin xyz="0 0 0" rpy="0 0 0"/>
      <geometry>
        <mesh filename="package://forklift_simulation/description/meshes/left_wheel.STL"/>
      </geometry>
      <material name="">
        <color rgba="0.29804 0.29804 0.29804 1"/>
      </material>
    </visual>
    <collision>
      <origin xyz="0 0 0" rpy="0 0 0"/>
      <geometry>
        <mesh filename="package://forklift_simulation/description/meshes/left_wheel.STL"/>
      </geometry>
    </collision>
  </link>

<!-- Steering Link -->
  <link name="steering">
    <inertial>
      <origin xyz="-6.8292E-09 -4.407E-06 -0.056201" rpy="0 0 0"/>
      <mass value="0.33222"/>
      <inertia ixx="0.38" ixy="0.19" ixz="0.21" iyy="0.42" iyz="0.19" izz="0.4"/>
    </inertial>
    <visual>
      <origin xyz="0 0 0" rpy="0 0 0"/>
      <geometry>
        <mesh filename="package://forklift_simulation/description/meshes/steering.STL"/>
      </geometry>
      <material name="">
        <color rgba="0.79216 0.81961 0.93333 1"/>
      </material>
    </visual>
    <collision>
      <origin xyz="0 0 0" rpy="0 0 0"/>
      <geometry>
        <mesh filename="package://forklift_simulation/description/meshes/steering.STL"/>
      </geometry>
    </collision>
  </link>

<!-- Steering Wheel Link -->
  <link name="steering_wheel">
    <inertial>
      <origin xyz="0.3904 -0.11856 -0.038687" rpy="0 0 0"/>
      <mass value="1.17"/>
      <inertia ixx="0" ixy="0" ixz="0" iyy="0" iyz="0" izz="0.01"/> 
      <!-- 30.826 -->
    </inertial>
    <visual>
      <origin xyz="0 0 0" rpy="0 0 0"/>
      <geometry>
        <mesh filename="package://forklift_simulation/description/meshes/steering_wheel.STL"/>
      </geometry>
      <material name="">
        <color rgba="1 1 1 1"/>
      </material>
    </visual>
    <collision>
      <origin xyz="0 0 0" rpy="0 0 0"/>
      <geometry>
        <mesh filename="package://forklift_simulation/description/meshes/steering_wheel.STL"/>
      </geometry>
    </collision>
  </link>

<!-- Fork Link -->
  <link name="fork">
    <inertial>
      <origin xyz="-0.17561 -6.252E-06 0.1217" rpy="0 0 0"/>
      <mass value="2.3509"/>
      <inertia ixx="0.025264" ixy="1.3441E-06" ixz="0.0064063" iyy="0.028348" iyz="-1.2913E-06" izz="0.026676"/>
    </inertial>
    <visual>
      <origin xyz="0 0 0" rpy="0 0 0"/>
      <geometry>
        <mesh filename="package://forklift_simulation/description/meshes/fork.STL"/>
      </geometry>
      <material name="">
        <color rgba="0.79216 0.81961 0.93333 1"/>
      </material>
    </visual>
    <collision>
      <origin xyz="0 0 0" rpy="0 0 0"/>
      <geometry>
        <mesh filename="package://forklift_simulation/description/meshes/fork.STL"/>
      </geometry>
    </collision>
  </link>

<!-- Lidar Link -->
  <link name="lidar">
    <inertial>
      <origin xyz="0.0082941 1.218E-15 -0.011499" rpy="0 0 0"/>
      <mass value="0.1467"/>
      <inertia ixx="6.2272E-05" ixy="-5.4283E-21" ixz="1.8866E-05" iyy="0.00010967" iyz="-7.2985E-21" izz="0.00012568"/>
    </inertial>
    <visual>
      <origin xyz="0 0 0" rpy="0 0 0"/>
      <geometry>
        <mesh filename="package://forklift_simulation/description/meshes/lidar.STL"/>
      </geometry>
      <material name="">
        <color rgba="0.79216 0.81961 0.93333 1"/>
      </material>
    </visual>
    <collision>
      <origin xyz="0 0 0" rpy="0 0 0"/>
      <geometry>
        <mesh filename="package://forklift_simulation/description/meshes/lidar.STL"/>
      </geometry>
    </collision>
  </link>

<!-- Kinect Link -->
  <link name="kinect">
    <inertial>
      <origin xyz="-0.022778 -6.1618E-07 0.037485" rpy="0 0 0"/>
      <mass value="0.20967"/>
      <inertia ixx="0.0018872" ixy="4.0979E-09" ixz="4.8229E-19" iyy="0.00019443" iyz="-2.8119E-10" izz="0.0020804"/>
    </inertial>
    <visual>
      <origin xyz="0 0 0" rpy="0 0 0"/>
      <geometry>
        <mesh filename="package://forklift_simulation/description/meshes/kinect.STL"/>
      </geometry>
      <material name="">
        <color rgba="0.79216 0.81961 0.93333 1"/>
      </material>
    </visual>
    <collision>
      <origin xyz="0 0 0" rpy="0 0 0"/>
      <geometry>
        <mesh filename="package://forklift_simulation/description/meshes/kinect.STL"/>
      </geometry>
    </collision>
  </link>

<!-- IMU Link -->
  <link name="imu">
   <inertial>
    <origin xyz="0.021199 1.2181E-14 -0.015895" rpy="0 0 0"/>
    <mass value="0.01"/>
    <inertia
      ixx="1.7987E-05"
      ixy="-2.0959E-21"
      ixz="-4.986E-21"
      iyy="0.00014163"
      iyz="7.3468E-37"
      izz="0.00014059" />
   </inertial>
   <visual>
    <origin xyz="0 0 0" rpy="0 0 0" />
    <geometry>
      <mesh filename="package://forklift_simulation/description/meshes/imu.STL" />
    </geometry>
    <material name="">
      <color rgba="0.79216 0.81961 0.93333 1" />
    </material>
   </visual>
   <collision>
    <origin xyz="0 0 0" rpy="0 0 0" />
    <geometry>
      <mesh filename="package://forklift_simulation/description/meshes/imu.STL" />
    </geometry>
   </collision>
  </link>



            <!-- ______________________Joints________________________-->


<!-- Chassis to Base Footprint Joint -->
  <joint name="chassis_base_footprint" type="fixed">
    <origin xyz="0 0 0.125" rpy="0 0 0"/>
    <parent link="base_footprint"/>
    <child link="chassis"/>
    <axis xyz="0 0 0"/>
    <!-- <limit lower= "0" upper= "0" effort= "0" velocity= "0"/> -->
  </joint>

<!-- Right Wheel Joint -->
  <joint name="right_wheel_joint" type="continuous">
    <origin xyz="0 -0.22 0" rpy="-1.5708 0 0"/>
    <parent link="chassis"/>
    <child link="right_wheel"/>
    <axis xyz="0 0 1"/>
  </joint>

<!-- Left Wheel Joint -->
  <joint name="left_wheel_joint" type="continuous">
    <origin xyz="0 0.22 0" rpy="-1.57079632679489 0 0"/>
    <parent link="chassis"/>
    <child link="left_wheel"/>
    <axis xyz="0 0 1"/>
  </joint>

<!-- Steering Joint -->
  <joint name="steering_joint" type="revolute">
    <origin xyz="-0.358 0 0.10508" rpy="0 0 0"/>
    <parent link="chassis"/>
    <child link="steering"/>
    <axis xyz="0 0 1"/>
    <limit lower="-1.5" upper="1.5" effort="3" velocity="10"/>
  </joint>

<!-- Steering Wheel Joint -->
 <joint name="steering_wheel_joint" type="continuous">
  <origin xyz="0 0 -0.13" rpy="-1.5707963267949 0 0"/>
  <parent link="steering"/>
  <child link="steering_wheel"/>
  <axis xyz="0 0 1"/>
 </joint>

<!-- Fork Joint -->
  <joint name="fork_joint" type="prismatic">
    <origin xyz="0.551 -0.0095001 -0.031" rpy="0 0 0"/>
    <parent link="chassis"/>
    <child link="fork"/>
    <axis xyz="0 0 1"/>
    <limit lower="0" upper="0.3" effort="0" velocity="0"/>
  </joint>

<!-- Lidar Joint -->
  <joint name="lidar_joint" type="fixed">
    <origin xyz="0.280500000000007 0 1.03720000000023" rpy="0 0 0"/>
    <parent link="chassis"/>
    <child link="lidar"/>
    <axis xyz="0 0 0"/>
  </joint>

<!-- IMU Joint -->
  <joint name="imu_joint" type="fixed">
    <origin xyz="0 0 0.508" rpy="0 0 0" />
    <parent link="chassis" />
    <child link="imu" />
  </joint>

<!-- Kinect Joint -->
  <joint name="kinect_joint" type="fixed">
    <origin xyz="0.40675 0.00020009 0.90951" rpy="0 0 0"/>
    <parent link="chassis"/>
    <child link="kinect"/>
    <axis xyz="0 0 0"/>
  </joint>

</robot>